Exception on /swagger [GET]
Traceback (most recent call last):
  File "C:\Users\UTILISATEUR\Desktop\WebAtrio\WebAtrio\env\lib\site-packages\flask\app.py", line 1473, in wsgi_app
    response = self.full_dispatch_request()
  File "C:\Users\UTILISATEUR\Desktop\WebAtrio\WebAtrio\env\lib\site-packages\flask\app.py", line 882, in full_dispatch_request
    rv = self.handle_user_exception(e)
  File "C:\Users\UTILISATEUR\Desktop\WebAtrio\WebAtrio\env\lib\site-packages\flask\app.py", line 880, in full_dispatch_request
    rv = self.dispatch_request()
  File "C:\Users\UTILISATEUR\Desktop\WebAtrio\WebAtrio\env\lib\site-packages\flask\app.py", line 865, in dispatch_request
    return self.ensure_sync(self.view_functions[rule.endpoint])(**view_args)  # type: ignore[no-any-return]
  File "C:\Users\UTILISATEUR\Desktop\WebAtrio\WebAtrio\WebAtrio\views.py", line 12, in swagger_ui
    return render_template('swagger_ui.html')
  File "C:\Users\UTILISATEUR\Desktop\WebAtrio\WebAtrio\env\lib\site-packages\flask\templating.py", line 149, in render_template
    template = app.jinja_env.get_or_select_template(template_name_or_list)
  File "C:\Users\UTILISATEUR\Desktop\WebAtrio\WebAtrio\env\lib\site-packages\jinja2\environment.py", line 1081, in get_or_select_template
    return self.get_template(template_name_or_list, parent, globals)
  File "C:\Users\UTILISATEUR\Desktop\WebAtrio\WebAtrio\env\lib\site-packages\jinja2\environment.py", line 1010, in get_template
    return self._load_template(name, globals)
  File "C:\Users\UTILISATEUR\Desktop\WebAtrio\WebAtrio\env\lib\site-packages\jinja2\environment.py", line 969, in _load_template
    template = self.loader.load(self, name, self.make_globals(globals))
  File "C:\Users\UTILISATEUR\Desktop\WebAtrio\WebAtrio\env\lib\site-packages\jinja2\loaders.py", line 125, in load
    source, filename, uptodate = self.get_source(environment, name)
  File "C:\Users\UTILISATEUR\Desktop\WebAtrio\WebAtrio\env\lib\site-packages\flask\templating.py", line 65, in get_source
    return self._get_source_fast(environment, template)
  File "C:\Users\UTILISATEUR\Desktop\WebAtrio\WebAtrio\env\lib\site-packages\flask\templating.py", line 99, in _get_source_fast
    raise TemplateNotFound(template)
jinja2.exceptions.TemplateNotFound: swagger_ui.html
Exception on /swagger [GET]
Traceback (most recent call last):
  File "C:\Users\UTILISATEUR\Desktop\WebAtrio\WebAtrio\env\lib\site-packages\flask\app.py", line 1473, in wsgi_app
    response = self.full_dispatch_request()
  File "C:\Users\UTILISATEUR\Desktop\WebAtrio\WebAtrio\env\lib\site-packages\flask\app.py", line 882, in full_dispatch_request
    rv = self.handle_user_exception(e)
  File "C:\Users\UTILISATEUR\Desktop\WebAtrio\WebAtrio\env\lib\site-packages\flask\app.py", line 880, in full_dispatch_request
    rv = self.dispatch_request()
  File "C:\Users\UTILISATEUR\Desktop\WebAtrio\WebAtrio\env\lib\site-packages\flask\app.py", line 865, in dispatch_request
    return self.ensure_sync(self.view_functions[rule.endpoint])(**view_args)  # type: ignore[no-any-return]
  File "C:\Users\UTILISATEUR\Desktop\WebAtrio\WebAtrio\WebAtrio\views.py", line 12, in swagger_ui
    return render_template('swagger_ui.html')
  File "C:\Users\UTILISATEUR\Desktop\WebAtrio\WebAtrio\env\lib\site-packages\flask\templating.py", line 149, in render_template
    template = app.jinja_env.get_or_select_template(template_name_or_list)
  File "C:\Users\UTILISATEUR\Desktop\WebAtrio\WebAtrio\env\lib\site-packages\jinja2\environment.py", line 1081, in get_or_select_template
    return self.get_template(template_name_or_list, parent, globals)
  File "C:\Users\UTILISATEUR\Desktop\WebAtrio\WebAtrio\env\lib\site-packages\jinja2\environment.py", line 1010, in get_template
    return self._load_template(name, globals)
  File "C:\Users\UTILISATEUR\Desktop\WebAtrio\WebAtrio\env\lib\site-packages\jinja2\environment.py", line 969, in _load_template
    template = self.loader.load(self, name, self.make_globals(globals))
  File "C:\Users\UTILISATEUR\Desktop\WebAtrio\WebAtrio\env\lib\site-packages\jinja2\loaders.py", line 125, in load
    source, filename, uptodate = self.get_source(environment, name)
  File "C:\Users\UTILISATEUR\Desktop\WebAtrio\WebAtrio\env\lib\site-packages\flask\templating.py", line 65, in get_source
    return self._get_source_fast(environment, template)
  File "C:\Users\UTILISATEUR\Desktop\WebAtrio\WebAtrio\env\lib\site-packages\flask\templating.py", line 99, in _get_source_fast
    raise TemplateNotFound(template)
jinja2.exceptions.TemplateNotFound: swagger_ui.html
Exception on /swagger-ui [GET]
Traceback (most recent call last):
  File "C:\Users\UTILISATEUR\Desktop\WebAtrio\WebAtrio\env\lib\site-packages\flask\app.py", line 1473, in wsgi_app
    response = self.full_dispatch_request()
  File "C:\Users\UTILISATEUR\Desktop\WebAtrio\WebAtrio\env\lib\site-packages\flask\app.py", line 882, in full_dispatch_request
    rv = self.handle_user_exception(e)
  File "C:\Users\UTILISATEUR\Desktop\WebAtrio\WebAtrio\env\lib\site-packages\flask\app.py", line 880, in full_dispatch_request
    rv = self.dispatch_request()
  File "C:\Users\UTILISATEUR\Desktop\WebAtrio\WebAtrio\env\lib\site-packages\flask\app.py", line 865, in dispatch_request
    return self.ensure_sync(self.view_functions[rule.endpoint])(**view_args)  # type: ignore[no-any-return]
  File "C:\Users\UTILISATEUR\Desktop\WebAtrio\WebAtrio\WebAtrio\views.py", line 12, in swagger_ui
    return render_template('swagger-ui.html', swagger_url=app.config['SWAGGER_URL'])
  File "C:\Users\UTILISATEUR\Desktop\WebAtrio\WebAtrio\env\lib\site-packages\flask\templating.py", line 149, in render_template
    template = app.jinja_env.get_or_select_template(template_name_or_list)
  File "C:\Users\UTILISATEUR\Desktop\WebAtrio\WebAtrio\env\lib\site-packages\jinja2\environment.py", line 1081, in get_or_select_template
    return self.get_template(template_name_or_list, parent, globals)
  File "C:\Users\UTILISATEUR\Desktop\WebAtrio\WebAtrio\env\lib\site-packages\jinja2\environment.py", line 1010, in get_template
    return self._load_template(name, globals)
  File "C:\Users\UTILISATEUR\Desktop\WebAtrio\WebAtrio\env\lib\site-packages\jinja2\environment.py", line 969, in _load_template
    template = self.loader.load(self, name, self.make_globals(globals))
  File "C:\Users\UTILISATEUR\Desktop\WebAtrio\WebAtrio\env\lib\site-packages\jinja2\loaders.py", line 125, in load
    source, filename, uptodate = self.get_source(environment, name)
  File "C:\Users\UTILISATEUR\Desktop\WebAtrio\WebAtrio\env\lib\site-packages\flask\templating.py", line 65, in get_source
    return self._get_source_fast(environment, template)
  File "C:\Users\UTILISATEUR\Desktop\WebAtrio\WebAtrio\env\lib\site-packages\flask\templating.py", line 99, in _get_source_fast
    raise TemplateNotFound(template)
jinja2.exceptions.TemplateNotFound: swagger-ui.html
Exception on /swagger-ui [GET]
Traceback (most recent call last):
  File "C:\Users\UTILISATEUR\Desktop\WebAtrio\WebAtrio\env\lib\site-packages\flask\app.py", line 1473, in wsgi_app
    response = self.full_dispatch_request()
  File "C:\Users\UTILISATEUR\Desktop\WebAtrio\WebAtrio\env\lib\site-packages\flask\app.py", line 882, in full_dispatch_request
    rv = self.handle_user_exception(e)
  File "C:\Users\UTILISATEUR\Desktop\WebAtrio\WebAtrio\env\lib\site-packages\flask\app.py", line 880, in full_dispatch_request
    rv = self.dispatch_request()
  File "C:\Users\UTILISATEUR\Desktop\WebAtrio\WebAtrio\env\lib\site-packages\flask\app.py", line 865, in dispatch_request
    return self.ensure_sync(self.view_functions[rule.endpoint])(**view_args)  # type: ignore[no-any-return]
  File "C:\Users\UTILISATEUR\Desktop\WebAtrio\WebAtrio\WebAtrio\views.py", line 12, in swagger_ui
    return render_template(app.config['SWAGGER_HTML_PATH'], json_path = app.config['SWAGGER_JSON_PATH'])
  File "C:\Users\UTILISATEUR\Desktop\WebAtrio\WebAtrio\env\lib\site-packages\flask\templating.py", line 149, in render_template
    template = app.jinja_env.get_or_select_template(template_name_or_list)
  File "C:\Users\UTILISATEUR\Desktop\WebAtrio\WebAtrio\env\lib\site-packages\jinja2\environment.py", line 1081, in get_or_select_template
    return self.get_template(template_name_or_list, parent, globals)
  File "C:\Users\UTILISATEUR\Desktop\WebAtrio\WebAtrio\env\lib\site-packages\jinja2\environment.py", line 1010, in get_template
    return self._load_template(name, globals)
  File "C:\Users\UTILISATEUR\Desktop\WebAtrio\WebAtrio\env\lib\site-packages\jinja2\environment.py", line 969, in _load_template
    template = self.loader.load(self, name, self.make_globals(globals))
  File "C:\Users\UTILISATEUR\Desktop\WebAtrio\WebAtrio\env\lib\site-packages\jinja2\loaders.py", line 125, in load
    source, filename, uptodate = self.get_source(environment, name)
  File "C:\Users\UTILISATEUR\Desktop\WebAtrio\WebAtrio\env\lib\site-packages\flask\templating.py", line 65, in get_source
    return self._get_source_fast(environment, template)
  File "C:\Users\UTILISATEUR\Desktop\WebAtrio\WebAtrio\env\lib\site-packages\flask\templating.py", line 99, in _get_source_fast
    raise TemplateNotFound(template)
jinja2.exceptions.TemplateNotFound: /static/swagger-ui.html
Exception on /swagger-ui [GET]
Traceback (most recent call last):
  File "C:\Users\UTILISATEUR\Desktop\WebAtrio\WebAtrio\env\lib\site-packages\flask\app.py", line 1473, in wsgi_app
    response = self.full_dispatch_request()
  File "C:\Users\UTILISATEUR\Desktop\WebAtrio\WebAtrio\env\lib\site-packages\flask\app.py", line 882, in full_dispatch_request
    rv = self.handle_user_exception(e)
  File "C:\Users\UTILISATEUR\Desktop\WebAtrio\WebAtrio\env\lib\site-packages\flask\app.py", line 880, in full_dispatch_request
    rv = self.dispatch_request()
  File "C:\Users\UTILISATEUR\Desktop\WebAtrio\WebAtrio\env\lib\site-packages\flask\app.py", line 865, in dispatch_request
    return self.ensure_sync(self.view_functions[rule.endpoint])(**view_args)  # type: ignore[no-any-return]
  File "C:\Users\UTILISATEUR\Desktop\WebAtrio\WebAtrio\WebAtrio\views.py", line 12, in swagger_ui
    return render_template(app.config['SWAGGER_HTML_PATH'], json_path = app.config['SWAGGER_JSON_PATH'])
  File "C:\Users\UTILISATEUR\Desktop\WebAtrio\WebAtrio\env\lib\site-packages\flask\templating.py", line 149, in render_template
    template = app.jinja_env.get_or_select_template(template_name_or_list)
  File "C:\Users\UTILISATEUR\Desktop\WebAtrio\WebAtrio\env\lib\site-packages\jinja2\environment.py", line 1081, in get_or_select_template
    return self.get_template(template_name_or_list, parent, globals)
  File "C:\Users\UTILISATEUR\Desktop\WebAtrio\WebAtrio\env\lib\site-packages\jinja2\environment.py", line 1010, in get_template
    return self._load_template(name, globals)
  File "C:\Users\UTILISATEUR\Desktop\WebAtrio\WebAtrio\env\lib\site-packages\jinja2\environment.py", line 969, in _load_template
    template = self.loader.load(self, name, self.make_globals(globals))
  File "C:\Users\UTILISATEUR\Desktop\WebAtrio\WebAtrio\env\lib\site-packages\jinja2\loaders.py", line 125, in load
    source, filename, uptodate = self.get_source(environment, name)
  File "C:\Users\UTILISATEUR\Desktop\WebAtrio\WebAtrio\env\lib\site-packages\flask\templating.py", line 65, in get_source
    return self._get_source_fast(environment, template)
  File "C:\Users\UTILISATEUR\Desktop\WebAtrio\WebAtrio\env\lib\site-packages\flask\templating.py", line 99, in _get_source_fast
    raise TemplateNotFound(template)
jinja2.exceptions.TemplateNotFound: /static/swagger-ui.html
Exception on /swagger [GET]
Traceback (most recent call last):
  File "C:\Users\UTILISATEUR\Desktop\WebAtrio\WebAtrio\env\lib\site-packages\flask\app.py", line 1473, in wsgi_app
    response = self.full_dispatch_request()
  File "C:\Users\UTILISATEUR\Desktop\WebAtrio\WebAtrio\env\lib\site-packages\flask\app.py", line 882, in full_dispatch_request
    rv = self.handle_user_exception(e)
  File "C:\Users\UTILISATEUR\Desktop\WebAtrio\WebAtrio\env\lib\site-packages\flask\app.py", line 880, in full_dispatch_request
    rv = self.dispatch_request()
  File "C:\Users\UTILISATEUR\Desktop\WebAtrio\WebAtrio\env\lib\site-packages\flask\app.py", line 865, in dispatch_request
    return self.ensure_sync(self.view_functions[rule.endpoint])(**view_args)  # type: ignore[no-any-return]
  File "C:\Users\UTILISATEUR\Desktop\WebAtrio\WebAtrio\WebAtrio\views.py", line 12, in swagger_ui
    return render_template('/static/swagger_ui.html')
  File "C:\Users\UTILISATEUR\Desktop\WebAtrio\WebAtrio\env\lib\site-packages\flask\templating.py", line 149, in render_template
    template = app.jinja_env.get_or_select_template(template_name_or_list)
  File "C:\Users\UTILISATEUR\Desktop\WebAtrio\WebAtrio\env\lib\site-packages\jinja2\environment.py", line 1081, in get_or_select_template
    return self.get_template(template_name_or_list, parent, globals)
  File "C:\Users\UTILISATEUR\Desktop\WebAtrio\WebAtrio\env\lib\site-packages\jinja2\environment.py", line 1010, in get_template
    return self._load_template(name, globals)
  File "C:\Users\UTILISATEUR\Desktop\WebAtrio\WebAtrio\env\lib\site-packages\jinja2\environment.py", line 969, in _load_template
    template = self.loader.load(self, name, self.make_globals(globals))
  File "C:\Users\UTILISATEUR\Desktop\WebAtrio\WebAtrio\env\lib\site-packages\jinja2\loaders.py", line 125, in load
    source, filename, uptodate = self.get_source(environment, name)
  File "C:\Users\UTILISATEUR\Desktop\WebAtrio\WebAtrio\env\lib\site-packages\flask\templating.py", line 65, in get_source
    return self._get_source_fast(environment, template)
  File "C:\Users\UTILISATEUR\Desktop\WebAtrio\WebAtrio\env\lib\site-packages\flask\templating.py", line 99, in _get_source_fast
    raise TemplateNotFound(template)
jinja2.exceptions.TemplateNotFound: /static/swagger_ui.html
Exception on /swagger [GET]
Traceback (most recent call last):
  File "C:\Users\UTILISATEUR\Desktop\WebAtrio\WebAtrio\env\lib\site-packages\flask\app.py", line 1473, in wsgi_app
    response = self.full_dispatch_request()
  File "C:\Users\UTILISATEUR\Desktop\WebAtrio\WebAtrio\env\lib\site-packages\flask\app.py", line 882, in full_dispatch_request
    rv = self.handle_user_exception(e)
  File "C:\Users\UTILISATEUR\Desktop\WebAtrio\WebAtrio\env\lib\site-packages\flask\app.py", line 880, in full_dispatch_request
    rv = self.dispatch_request()
  File "C:\Users\UTILISATEUR\Desktop\WebAtrio\WebAtrio\env\lib\site-packages\flask\app.py", line 865, in dispatch_request
    return self.ensure_sync(self.view_functions[rule.endpoint])(**view_args)  # type: ignore[no-any-return]
  File "C:\Users\UTILISATEUR\Desktop\WebAtrio\WebAtrio\WebAtrio\views.py", line 12, in swagger_ui
    return render_template('static/swagger_ui.html')
  File "C:\Users\UTILISATEUR\Desktop\WebAtrio\WebAtrio\env\lib\site-packages\flask\templating.py", line 149, in render_template
    template = app.jinja_env.get_or_select_template(template_name_or_list)
  File "C:\Users\UTILISATEUR\Desktop\WebAtrio\WebAtrio\env\lib\site-packages\jinja2\environment.py", line 1081, in get_or_select_template
    return self.get_template(template_name_or_list, parent, globals)
  File "C:\Users\UTILISATEUR\Desktop\WebAtrio\WebAtrio\env\lib\site-packages\jinja2\environment.py", line 1010, in get_template
    return self._load_template(name, globals)
  File "C:\Users\UTILISATEUR\Desktop\WebAtrio\WebAtrio\env\lib\site-packages\jinja2\environment.py", line 969, in _load_template
    template = self.loader.load(self, name, self.make_globals(globals))
  File "C:\Users\UTILISATEUR\Desktop\WebAtrio\WebAtrio\env\lib\site-packages\jinja2\loaders.py", line 125, in load
    source, filename, uptodate = self.get_source(environment, name)
  File "C:\Users\UTILISATEUR\Desktop\WebAtrio\WebAtrio\env\lib\site-packages\flask\templating.py", line 65, in get_source
    return self._get_source_fast(environment, template)
  File "C:\Users\UTILISATEUR\Desktop\WebAtrio\WebAtrio\env\lib\site-packages\flask\templating.py", line 99, in _get_source_fast
    raise TemplateNotFound(template)
jinja2.exceptions.TemplateNotFound: static/swagger_ui.html
Exception on /jobs/er/companies [GET]
Traceback (most recent call last):
  File "C:\Users\UTILISATEUR\Desktop\WebAtrio\WebAtrio\env\lib\site-packages\sqlalchemy\engine\base.py", line 1971, in _exec_single_context
    self.dialect.do_execute(
  File "C:\Users\UTILISATEUR\Desktop\WebAtrio\WebAtrio\env\lib\site-packages\sqlalchemy\engine\default.py", line 919, in do_execute
    cursor.execute(statement, parameters)
sqlite3.OperationalError: no such table: jobs

The above exception was the direct cause of the following exception:

Traceback (most recent call last):
  File "C:\Users\UTILISATEUR\Desktop\WebAtrio\WebAtrio\env\lib\site-packages\flask\app.py", line 1473, in wsgi_app
    response = self.full_dispatch_request()
  File "C:\Users\UTILISATEUR\Desktop\WebAtrio\WebAtrio\env\lib\site-packages\flask\app.py", line 882, in full_dispatch_request
    rv = self.handle_user_exception(e)
  File "C:\Users\UTILISATEUR\Desktop\WebAtrio\WebAtrio\env\lib\site-packages\flask\app.py", line 880, in full_dispatch_request
    rv = self.dispatch_request()
  File "C:\Users\UTILISATEUR\Desktop\WebAtrio\WebAtrio\env\lib\site-packages\flask\app.py", line 865, in dispatch_request
    return self.ensure_sync(self.view_functions[rule.endpoint])(**view_args)  # type: ignore[no-any-return]
  File "C:\Users\UTILISATEUR\Desktop\WebAtrio\WebAtrio\WebAtrio\views.py", line 207, in get_companies_by_job
    jobs = Job.query.filter_by(position=job_name).all()
  File "C:\Users\UTILISATEUR\Desktop\WebAtrio\WebAtrio\env\lib\site-packages\sqlalchemy\orm\query.py", line 2673, in all
    return self._iter().all()  # type: ignore
  File "C:\Users\UTILISATEUR\Desktop\WebAtrio\WebAtrio\env\lib\site-packages\sqlalchemy\orm\query.py", line 2827, in _iter
    result: Union[ScalarResult[_T], Result[_T]] = self.session.execute(
  File "C:\Users\UTILISATEUR\Desktop\WebAtrio\WebAtrio\env\lib\site-packages\sqlalchemy\orm\session.py", line 2306, in execute
    return self._execute_internal(
  File "C:\Users\UTILISATEUR\Desktop\WebAtrio\WebAtrio\env\lib\site-packages\sqlalchemy\orm\session.py", line 2191, in _execute_internal
    result: Result[Any] = compile_state_cls.orm_execute_statement(
  File "C:\Users\UTILISATEUR\Desktop\WebAtrio\WebAtrio\env\lib\site-packages\sqlalchemy\orm\context.py", line 293, in orm_execute_statement
    result = conn.execute(
  File "C:\Users\UTILISATEUR\Desktop\WebAtrio\WebAtrio\env\lib\site-packages\sqlalchemy\engine\base.py", line 1422, in execute
    return meth(
  File "C:\Users\UTILISATEUR\Desktop\WebAtrio\WebAtrio\env\lib\site-packages\sqlalchemy\sql\elements.py", line 514, in _execute_on_connection
    return connection._execute_clauseelement(
  File "C:\Users\UTILISATEUR\Desktop\WebAtrio\WebAtrio\env\lib\site-packages\sqlalchemy\engine\base.py", line 1644, in _execute_clauseelement
    ret = self._execute_context(
  File "C:\Users\UTILISATEUR\Desktop\WebAtrio\WebAtrio\env\lib\site-packages\sqlalchemy\engine\base.py", line 1850, in _execute_context
    return self._exec_single_context(
  File "C:\Users\UTILISATEUR\Desktop\WebAtrio\WebAtrio\env\lib\site-packages\sqlalchemy\engine\base.py", line 1990, in _exec_single_context
    self._handle_dbapi_exception(
  File "C:\Users\UTILISATEUR\Desktop\WebAtrio\WebAtrio\env\lib\site-packages\sqlalchemy\engine\base.py", line 2357, in _handle_dbapi_exception
    raise sqlalchemy_exception.with_traceback(exc_info[2]) from e
  File "C:\Users\UTILISATEUR\Desktop\WebAtrio\WebAtrio\env\lib\site-packages\sqlalchemy\engine\base.py", line 1971, in _exec_single_context
    self.dialect.do_execute(
  File "C:\Users\UTILISATEUR\Desktop\WebAtrio\WebAtrio\env\lib\site-packages\sqlalchemy\engine\default.py", line 919, in do_execute
    cursor.execute(statement, parameters)
sqlalchemy.exc.OperationalError: (sqlite3.OperationalError) no such table: jobs
[SQL: SELECT jobs.id AS jobs_id, jobs.position AS jobs_position, jobs.start_date AS jobs_start_date, jobs.end_date AS jobs_end_date, jobs.person_id AS jobs_person_id, jobs.company_id AS jobs_company_id 
FROM jobs 
WHERE jobs.position = ?]
[parameters: ('er',)]
(Background on this error at: https://sqlalche.me/e/20/e3q8)
Exception on /persons [GET]
Traceback (most recent call last):
  File "C:\Users\UTILISATEUR\Desktop\WebAtrio\WebAtrio\env\lib\site-packages\sqlalchemy\engine\base.py", line 1971, in _exec_single_context
    self.dialect.do_execute(
  File "C:\Users\UTILISATEUR\Desktop\WebAtrio\WebAtrio\env\lib\site-packages\sqlalchemy\engine\default.py", line 919, in do_execute
    cursor.execute(statement, parameters)
sqlite3.OperationalError: no such table: persons

The above exception was the direct cause of the following exception:

Traceback (most recent call last):
  File "C:\Users\UTILISATEUR\Desktop\WebAtrio\WebAtrio\env\lib\site-packages\flask\app.py", line 1473, in wsgi_app
    response = self.full_dispatch_request()
  File "C:\Users\UTILISATEUR\Desktop\WebAtrio\WebAtrio\env\lib\site-packages\flask\app.py", line 882, in full_dispatch_request
    rv = self.handle_user_exception(e)
  File "C:\Users\UTILISATEUR\Desktop\WebAtrio\WebAtrio\env\lib\site-packages\flask\app.py", line 880, in full_dispatch_request
    rv = self.dispatch_request()
  File "C:\Users\UTILISATEUR\Desktop\WebAtrio\WebAtrio\env\lib\site-packages\flask\app.py", line 865, in dispatch_request
    return self.ensure_sync(self.view_functions[rule.endpoint])(**view_args)  # type: ignore[no-any-return]
  File "C:\Users\UTILISATEUR\Desktop\WebAtrio\WebAtrio\WebAtrio\views.py", line 17, in handle_persons
    persons = Person.query.order_by(Person.last_name).all()
  File "C:\Users\UTILISATEUR\Desktop\WebAtrio\WebAtrio\env\lib\site-packages\sqlalchemy\orm\query.py", line 2673, in all
    return self._iter().all()  # type: ignore
  File "C:\Users\UTILISATEUR\Desktop\WebAtrio\WebAtrio\env\lib\site-packages\sqlalchemy\orm\query.py", line 2827, in _iter
    result: Union[ScalarResult[_T], Result[_T]] = self.session.execute(
  File "C:\Users\UTILISATEUR\Desktop\WebAtrio\WebAtrio\env\lib\site-packages\sqlalchemy\orm\session.py", line 2306, in execute
    return self._execute_internal(
  File "C:\Users\UTILISATEUR\Desktop\WebAtrio\WebAtrio\env\lib\site-packages\sqlalchemy\orm\session.py", line 2191, in _execute_internal
    result: Result[Any] = compile_state_cls.orm_execute_statement(
  File "C:\Users\UTILISATEUR\Desktop\WebAtrio\WebAtrio\env\lib\site-packages\sqlalchemy\orm\context.py", line 293, in orm_execute_statement
    result = conn.execute(
  File "C:\Users\UTILISATEUR\Desktop\WebAtrio\WebAtrio\env\lib\site-packages\sqlalchemy\engine\base.py", line 1422, in execute
    return meth(
  File "C:\Users\UTILISATEUR\Desktop\WebAtrio\WebAtrio\env\lib\site-packages\sqlalchemy\sql\elements.py", line 514, in _execute_on_connection
    return connection._execute_clauseelement(
  File "C:\Users\UTILISATEUR\Desktop\WebAtrio\WebAtrio\env\lib\site-packages\sqlalchemy\engine\base.py", line 1644, in _execute_clauseelement
    ret = self._execute_context(
  File "C:\Users\UTILISATEUR\Desktop\WebAtrio\WebAtrio\env\lib\site-packages\sqlalchemy\engine\base.py", line 1850, in _execute_context
    return self._exec_single_context(
  File "C:\Users\UTILISATEUR\Desktop\WebAtrio\WebAtrio\env\lib\site-packages\sqlalchemy\engine\base.py", line 1990, in _exec_single_context
    self._handle_dbapi_exception(
  File "C:\Users\UTILISATEUR\Desktop\WebAtrio\WebAtrio\env\lib\site-packages\sqlalchemy\engine\base.py", line 2357, in _handle_dbapi_exception
    raise sqlalchemy_exception.with_traceback(exc_info[2]) from e
  File "C:\Users\UTILISATEUR\Desktop\WebAtrio\WebAtrio\env\lib\site-packages\sqlalchemy\engine\base.py", line 1971, in _exec_single_context
    self.dialect.do_execute(
  File "C:\Users\UTILISATEUR\Desktop\WebAtrio\WebAtrio\env\lib\site-packages\sqlalchemy\engine\default.py", line 919, in do_execute
    cursor.execute(statement, parameters)
sqlalchemy.exc.OperationalError: (sqlite3.OperationalError) no such table: persons
[SQL: SELECT persons.id AS persons_id, persons.first_name AS persons_first_name, persons.last_name AS persons_last_name, persons.birth_date AS persons_birth_date 
FROM persons ORDER BY persons.last_name]
(Background on this error at: https://sqlalche.me/e/20/e3q8)
Exception on /persons [GET]
Traceback (most recent call last):
  File "C:\Users\UTILISATEUR\Desktop\WebAtrio\WebAtrio\env\lib\site-packages\sqlalchemy\engine\base.py", line 1971, in _exec_single_context
    self.dialect.do_execute(
  File "C:\Users\UTILISATEUR\Desktop\WebAtrio\WebAtrio\env\lib\site-packages\sqlalchemy\engine\default.py", line 919, in do_execute
    cursor.execute(statement, parameters)
sqlite3.OperationalError: no such table: persons

The above exception was the direct cause of the following exception:

Traceback (most recent call last):
  File "C:\Users\UTILISATEUR\Desktop\WebAtrio\WebAtrio\env\lib\site-packages\flask\app.py", line 1473, in wsgi_app
    response = self.full_dispatch_request()
  File "C:\Users\UTILISATEUR\Desktop\WebAtrio\WebAtrio\env\lib\site-packages\flask\app.py", line 882, in full_dispatch_request
    rv = self.handle_user_exception(e)
  File "C:\Users\UTILISATEUR\Desktop\WebAtrio\WebAtrio\env\lib\site-packages\flask\app.py", line 880, in full_dispatch_request
    rv = self.dispatch_request()
  File "C:\Users\UTILISATEUR\Desktop\WebAtrio\WebAtrio\env\lib\site-packages\flask\app.py", line 865, in dispatch_request
    return self.ensure_sync(self.view_functions[rule.endpoint])(**view_args)  # type: ignore[no-any-return]
  File "C:\Users\UTILISATEUR\Desktop\WebAtrio\WebAtrio\WebAtrio\views.py", line 17, in handle_persons
    persons = Person.query.order_by(Person.last_name).all()
  File "C:\Users\UTILISATEUR\Desktop\WebAtrio\WebAtrio\env\lib\site-packages\sqlalchemy\orm\query.py", line 2673, in all
    return self._iter().all()  # type: ignore
  File "C:\Users\UTILISATEUR\Desktop\WebAtrio\WebAtrio\env\lib\site-packages\sqlalchemy\orm\query.py", line 2827, in _iter
    result: Union[ScalarResult[_T], Result[_T]] = self.session.execute(
  File "C:\Users\UTILISATEUR\Desktop\WebAtrio\WebAtrio\env\lib\site-packages\sqlalchemy\orm\session.py", line 2306, in execute
    return self._execute_internal(
  File "C:\Users\UTILISATEUR\Desktop\WebAtrio\WebAtrio\env\lib\site-packages\sqlalchemy\orm\session.py", line 2191, in _execute_internal
    result: Result[Any] = compile_state_cls.orm_execute_statement(
  File "C:\Users\UTILISATEUR\Desktop\WebAtrio\WebAtrio\env\lib\site-packages\sqlalchemy\orm\context.py", line 293, in orm_execute_statement
    result = conn.execute(
  File "C:\Users\UTILISATEUR\Desktop\WebAtrio\WebAtrio\env\lib\site-packages\sqlalchemy\engine\base.py", line 1422, in execute
    return meth(
  File "C:\Users\UTILISATEUR\Desktop\WebAtrio\WebAtrio\env\lib\site-packages\sqlalchemy\sql\elements.py", line 514, in _execute_on_connection
    return connection._execute_clauseelement(
  File "C:\Users\UTILISATEUR\Desktop\WebAtrio\WebAtrio\env\lib\site-packages\sqlalchemy\engine\base.py", line 1644, in _execute_clauseelement
    ret = self._execute_context(
  File "C:\Users\UTILISATEUR\Desktop\WebAtrio\WebAtrio\env\lib\site-packages\sqlalchemy\engine\base.py", line 1850, in _execute_context
    return self._exec_single_context(
  File "C:\Users\UTILISATEUR\Desktop\WebAtrio\WebAtrio\env\lib\site-packages\sqlalchemy\engine\base.py", line 1990, in _exec_single_context
    self._handle_dbapi_exception(
  File "C:\Users\UTILISATEUR\Desktop\WebAtrio\WebAtrio\env\lib\site-packages\sqlalchemy\engine\base.py", line 2357, in _handle_dbapi_exception
    raise sqlalchemy_exception.with_traceback(exc_info[2]) from e
  File "C:\Users\UTILISATEUR\Desktop\WebAtrio\WebAtrio\env\lib\site-packages\sqlalchemy\engine\base.py", line 1971, in _exec_single_context
    self.dialect.do_execute(
  File "C:\Users\UTILISATEUR\Desktop\WebAtrio\WebAtrio\env\lib\site-packages\sqlalchemy\engine\default.py", line 919, in do_execute
    cursor.execute(statement, parameters)
sqlalchemy.exc.OperationalError: (sqlite3.OperationalError) no such table: persons
[SQL: SELECT persons.id AS persons_id, persons.first_name AS persons_first_name, persons.last_name AS persons_last_name, persons.birth_date AS persons_birth_date 
FROM persons ORDER BY persons.last_name]
(Background on this error at: https://sqlalche.me/e/20/e3q8)
Exception on /persons [GET]
Traceback (most recent call last):
  File "C:\Users\UTILISATEUR\Desktop\WebAtrio\WebAtrio\env\lib\site-packages\sqlalchemy\engine\base.py", line 1971, in _exec_single_context
    self.dialect.do_execute(
  File "C:\Users\UTILISATEUR\Desktop\WebAtrio\WebAtrio\env\lib\site-packages\sqlalchemy\engine\default.py", line 919, in do_execute
    cursor.execute(statement, parameters)
sqlite3.OperationalError: no such table: persons

The above exception was the direct cause of the following exception:

Traceback (most recent call last):
  File "C:\Users\UTILISATEUR\Desktop\WebAtrio\WebAtrio\env\lib\site-packages\flask\app.py", line 1473, in wsgi_app
    response = self.full_dispatch_request()
  File "C:\Users\UTILISATEUR\Desktop\WebAtrio\WebAtrio\env\lib\site-packages\flask\app.py", line 882, in full_dispatch_request
    rv = self.handle_user_exception(e)
  File "C:\Users\UTILISATEUR\Desktop\WebAtrio\WebAtrio\env\lib\site-packages\flask\app.py", line 880, in full_dispatch_request
    rv = self.dispatch_request()
  File "C:\Users\UTILISATEUR\Desktop\WebAtrio\WebAtrio\env\lib\site-packages\flask\app.py", line 865, in dispatch_request
    return self.ensure_sync(self.view_functions[rule.endpoint])(**view_args)  # type: ignore[no-any-return]
  File "C:\Users\UTILISATEUR\Desktop\WebAtrio\WebAtrio\WebAtrio\views.py", line 17, in handle_persons
    persons = Person.query.order_by(Person.last_name).all()
  File "C:\Users\UTILISATEUR\Desktop\WebAtrio\WebAtrio\env\lib\site-packages\sqlalchemy\orm\query.py", line 2673, in all
    return self._iter().all()  # type: ignore
  File "C:\Users\UTILISATEUR\Desktop\WebAtrio\WebAtrio\env\lib\site-packages\sqlalchemy\orm\query.py", line 2827, in _iter
    result: Union[ScalarResult[_T], Result[_T]] = self.session.execute(
  File "C:\Users\UTILISATEUR\Desktop\WebAtrio\WebAtrio\env\lib\site-packages\sqlalchemy\orm\session.py", line 2306, in execute
    return self._execute_internal(
  File "C:\Users\UTILISATEUR\Desktop\WebAtrio\WebAtrio\env\lib\site-packages\sqlalchemy\orm\session.py", line 2191, in _execute_internal
    result: Result[Any] = compile_state_cls.orm_execute_statement(
  File "C:\Users\UTILISATEUR\Desktop\WebAtrio\WebAtrio\env\lib\site-packages\sqlalchemy\orm\context.py", line 293, in orm_execute_statement
    result = conn.execute(
  File "C:\Users\UTILISATEUR\Desktop\WebAtrio\WebAtrio\env\lib\site-packages\sqlalchemy\engine\base.py", line 1422, in execute
    return meth(
  File "C:\Users\UTILISATEUR\Desktop\WebAtrio\WebAtrio\env\lib\site-packages\sqlalchemy\sql\elements.py", line 514, in _execute_on_connection
    return connection._execute_clauseelement(
  File "C:\Users\UTILISATEUR\Desktop\WebAtrio\WebAtrio\env\lib\site-packages\sqlalchemy\engine\base.py", line 1644, in _execute_clauseelement
    ret = self._execute_context(
  File "C:\Users\UTILISATEUR\Desktop\WebAtrio\WebAtrio\env\lib\site-packages\sqlalchemy\engine\base.py", line 1850, in _execute_context
    return self._exec_single_context(
  File "C:\Users\UTILISATEUR\Desktop\WebAtrio\WebAtrio\env\lib\site-packages\sqlalchemy\engine\base.py", line 1990, in _exec_single_context
    self._handle_dbapi_exception(
  File "C:\Users\UTILISATEUR\Desktop\WebAtrio\WebAtrio\env\lib\site-packages\sqlalchemy\engine\base.py", line 2357, in _handle_dbapi_exception
    raise sqlalchemy_exception.with_traceback(exc_info[2]) from e
  File "C:\Users\UTILISATEUR\Desktop\WebAtrio\WebAtrio\env\lib\site-packages\sqlalchemy\engine\base.py", line 1971, in _exec_single_context
    self.dialect.do_execute(
  File "C:\Users\UTILISATEUR\Desktop\WebAtrio\WebAtrio\env\lib\site-packages\sqlalchemy\engine\default.py", line 919, in do_execute
    cursor.execute(statement, parameters)
sqlalchemy.exc.OperationalError: (sqlite3.OperationalError) no such table: persons
[SQL: SELECT persons.id AS persons_id, persons.first_name AS persons_first_name, persons.last_name AS persons_last_name, persons.birth_date AS persons_birth_date 
FROM persons ORDER BY persons.last_name]
(Background on this error at: https://sqlalche.me/e/20/e3q8)
Exception on /persons/1 [GET]
Traceback (most recent call last):
  File "C:\Users\UTILISATEUR\Desktop\WebAtrio\WebAtrio\env\lib\site-packages\sqlalchemy\engine\base.py", line 1971, in _exec_single_context
    self.dialect.do_execute(
  File "C:\Users\UTILISATEUR\Desktop\WebAtrio\WebAtrio\env\lib\site-packages\sqlalchemy\engine\default.py", line 919, in do_execute
    cursor.execute(statement, parameters)
sqlite3.OperationalError: no such table: persons

The above exception was the direct cause of the following exception:

Traceback (most recent call last):
  File "C:\Users\UTILISATEUR\Desktop\WebAtrio\WebAtrio\env\lib\site-packages\flask\app.py", line 1473, in wsgi_app
    response = self.full_dispatch_request()
  File "C:\Users\UTILISATEUR\Desktop\WebAtrio\WebAtrio\env\lib\site-packages\flask\app.py", line 882, in full_dispatch_request
    rv = self.handle_user_exception(e)
  File "C:\Users\UTILISATEUR\Desktop\WebAtrio\WebAtrio\env\lib\site-packages\flask\app.py", line 880, in full_dispatch_request
    rv = self.dispatch_request()
  File "C:\Users\UTILISATEUR\Desktop\WebAtrio\WebAtrio\env\lib\site-packages\flask\app.py", line 865, in dispatch_request
    return self.ensure_sync(self.view_functions[rule.endpoint])(**view_args)  # type: ignore[no-any-return]
  File "C:\Users\UTILISATEUR\Desktop\WebAtrio\WebAtrio\WebAtrio\views.py", line 44, in handle_person
    person = Person.query.get_or_404(person_id)
  File "C:\Users\UTILISATEUR\Desktop\WebAtrio\WebAtrio\env\lib\site-packages\flask_sqlalchemy\query.py", line 30, in get_or_404
    rv = self.get(ident)
  File "<string>", line 2, in get
  File "C:\Users\UTILISATEUR\Desktop\WebAtrio\WebAtrio\env\lib\site-packages\sqlalchemy\util\deprecations.py", line 386, in warned
    return fn(*args, **kwargs)  # type: ignore[no-any-return]
  File "C:\Users\UTILISATEUR\Desktop\WebAtrio\WebAtrio\env\lib\site-packages\sqlalchemy\orm\query.py", line 1127, in get
    return self._get_impl(ident, loading.load_on_pk_identity)
  File "C:\Users\UTILISATEUR\Desktop\WebAtrio\WebAtrio\env\lib\site-packages\sqlalchemy\orm\query.py", line 1136, in _get_impl
    return self.session._get_impl(
  File "C:\Users\UTILISATEUR\Desktop\WebAtrio\WebAtrio\env\lib\site-packages\sqlalchemy\orm\session.py", line 3817, in _get_impl
    return db_load_fn(
  File "C:\Users\UTILISATEUR\Desktop\WebAtrio\WebAtrio\env\lib\site-packages\sqlalchemy\orm\loading.py", line 694, in load_on_pk_identity
    session.execute(
  File "C:\Users\UTILISATEUR\Desktop\WebAtrio\WebAtrio\env\lib\site-packages\sqlalchemy\orm\session.py", line 2306, in execute
    return self._execute_internal(
  File "C:\Users\UTILISATEUR\Desktop\WebAtrio\WebAtrio\env\lib\site-packages\sqlalchemy\orm\session.py", line 2191, in _execute_internal
    result: Result[Any] = compile_state_cls.orm_execute_statement(
  File "C:\Users\UTILISATEUR\Desktop\WebAtrio\WebAtrio\env\lib\site-packages\sqlalchemy\orm\context.py", line 293, in orm_execute_statement
    result = conn.execute(
  File "C:\Users\UTILISATEUR\Desktop\WebAtrio\WebAtrio\env\lib\site-packages\sqlalchemy\engine\base.py", line 1422, in execute
    return meth(
  File "C:\Users\UTILISATEUR\Desktop\WebAtrio\WebAtrio\env\lib\site-packages\sqlalchemy\sql\elements.py", line 514, in _execute_on_connection
    return connection._execute_clauseelement(
  File "C:\Users\UTILISATEUR\Desktop\WebAtrio\WebAtrio\env\lib\site-packages\sqlalchemy\engine\base.py", line 1644, in _execute_clauseelement
    ret = self._execute_context(
  File "C:\Users\UTILISATEUR\Desktop\WebAtrio\WebAtrio\env\lib\site-packages\sqlalchemy\engine\base.py", line 1850, in _execute_context
    return self._exec_single_context(
  File "C:\Users\UTILISATEUR\Desktop\WebAtrio\WebAtrio\env\lib\site-packages\sqlalchemy\engine\base.py", line 1990, in _exec_single_context
    self._handle_dbapi_exception(
  File "C:\Users\UTILISATEUR\Desktop\WebAtrio\WebAtrio\env\lib\site-packages\sqlalchemy\engine\base.py", line 2357, in _handle_dbapi_exception
    raise sqlalchemy_exception.with_traceback(exc_info[2]) from e
  File "C:\Users\UTILISATEUR\Desktop\WebAtrio\WebAtrio\env\lib\site-packages\sqlalchemy\engine\base.py", line 1971, in _exec_single_context
    self.dialect.do_execute(
  File "C:\Users\UTILISATEUR\Desktop\WebAtrio\WebAtrio\env\lib\site-packages\sqlalchemy\engine\default.py", line 919, in do_execute
    cursor.execute(statement, parameters)
sqlalchemy.exc.OperationalError: (sqlite3.OperationalError) no such table: persons
[SQL: SELECT persons.id AS persons_id, persons.first_name AS persons_first_name, persons.last_name AS persons_last_name, persons.birth_date AS persons_birth_date 
FROM persons 
WHERE persons.id = ?]
[parameters: (1,)]
(Background on this error at: https://sqlalche.me/e/20/e3q8)
Exception on /persons [GET]
Traceback (most recent call last):
  File "C:\Users\UTILISATEUR\Desktop\WebAtrio\WebAtrio\env\lib\site-packages\sqlalchemy\engine\base.py", line 1971, in _exec_single_context
    self.dialect.do_execute(
  File "C:\Users\UTILISATEUR\Desktop\WebAtrio\WebAtrio\env\lib\site-packages\sqlalchemy\engine\default.py", line 919, in do_execute
    cursor.execute(statement, parameters)
sqlite3.OperationalError: no such table: persons

The above exception was the direct cause of the following exception:

Traceback (most recent call last):
  File "C:\Users\UTILISATEUR\Desktop\WebAtrio\WebAtrio\env\lib\site-packages\flask\app.py", line 1473, in wsgi_app
    response = self.full_dispatch_request()
  File "C:\Users\UTILISATEUR\Desktop\WebAtrio\WebAtrio\env\lib\site-packages\flask\app.py", line 882, in full_dispatch_request
    rv = self.handle_user_exception(e)
  File "C:\Users\UTILISATEUR\Desktop\WebAtrio\WebAtrio\env\lib\site-packages\flask\app.py", line 880, in full_dispatch_request
    rv = self.dispatch_request()
  File "C:\Users\UTILISATEUR\Desktop\WebAtrio\WebAtrio\env\lib\site-packages\flask\app.py", line 865, in dispatch_request
    return self.ensure_sync(self.view_functions[rule.endpoint])(**view_args)  # type: ignore[no-any-return]
  File "C:\Users\UTILISATEUR\Desktop\WebAtrio\WebAtrio\WebAtrio\views.py", line 17, in handle_persons
    persons = Person.query.order_by(Person.last_name).all()
  File "C:\Users\UTILISATEUR\Desktop\WebAtrio\WebAtrio\env\lib\site-packages\sqlalchemy\orm\query.py", line 2673, in all
    return self._iter().all()  # type: ignore
  File "C:\Users\UTILISATEUR\Desktop\WebAtrio\WebAtrio\env\lib\site-packages\sqlalchemy\orm\query.py", line 2827, in _iter
    result: Union[ScalarResult[_T], Result[_T]] = self.session.execute(
  File "C:\Users\UTILISATEUR\Desktop\WebAtrio\WebAtrio\env\lib\site-packages\sqlalchemy\orm\session.py", line 2306, in execute
    return self._execute_internal(
  File "C:\Users\UTILISATEUR\Desktop\WebAtrio\WebAtrio\env\lib\site-packages\sqlalchemy\orm\session.py", line 2191, in _execute_internal
    result: Result[Any] = compile_state_cls.orm_execute_statement(
  File "C:\Users\UTILISATEUR\Desktop\WebAtrio\WebAtrio\env\lib\site-packages\sqlalchemy\orm\context.py", line 293, in orm_execute_statement
    result = conn.execute(
  File "C:\Users\UTILISATEUR\Desktop\WebAtrio\WebAtrio\env\lib\site-packages\sqlalchemy\engine\base.py", line 1422, in execute
    return meth(
  File "C:\Users\UTILISATEUR\Desktop\WebAtrio\WebAtrio\env\lib\site-packages\sqlalchemy\sql\elements.py", line 514, in _execute_on_connection
    return connection._execute_clauseelement(
  File "C:\Users\UTILISATEUR\Desktop\WebAtrio\WebAtrio\env\lib\site-packages\sqlalchemy\engine\base.py", line 1644, in _execute_clauseelement
    ret = self._execute_context(
  File "C:\Users\UTILISATEUR\Desktop\WebAtrio\WebAtrio\env\lib\site-packages\sqlalchemy\engine\base.py", line 1850, in _execute_context
    return self._exec_single_context(
  File "C:\Users\UTILISATEUR\Desktop\WebAtrio\WebAtrio\env\lib\site-packages\sqlalchemy\engine\base.py", line 1990, in _exec_single_context
    self._handle_dbapi_exception(
  File "C:\Users\UTILISATEUR\Desktop\WebAtrio\WebAtrio\env\lib\site-packages\sqlalchemy\engine\base.py", line 2357, in _handle_dbapi_exception
    raise sqlalchemy_exception.with_traceback(exc_info[2]) from e
  File "C:\Users\UTILISATEUR\Desktop\WebAtrio\WebAtrio\env\lib\site-packages\sqlalchemy\engine\base.py", line 1971, in _exec_single_context
    self.dialect.do_execute(
  File "C:\Users\UTILISATEUR\Desktop\WebAtrio\WebAtrio\env\lib\site-packages\sqlalchemy\engine\default.py", line 919, in do_execute
    cursor.execute(statement, parameters)
sqlalchemy.exc.OperationalError: (sqlite3.OperationalError) no such table: persons
[SQL: SELECT persons.id AS persons_id, persons.first_name AS persons_first_name, persons.last_name AS persons_last_name, persons.birth_date AS persons_birth_date 
FROM persons ORDER BY persons.last_name]
(Background on this error at: https://sqlalche.me/e/20/e3q8)
Database initialized !
Exception on / [GET]
Traceback (most recent call last):
  File "C:\Users\UTILISATEUR\Desktop\WebAtrio\WebAtrio\env\lib\site-packages\flask\app.py", line 1473, in wsgi_app
    response = self.full_dispatch_request()
  File "C:\Users\UTILISATEUR\Desktop\WebAtrio\WebAtrio\env\lib\site-packages\flask\app.py", line 882, in full_dispatch_request
    rv = self.handle_user_exception(e)
  File "C:\Users\UTILISATEUR\Desktop\WebAtrio\WebAtrio\env\lib\site-packages\flask\app.py", line 880, in full_dispatch_request
    rv = self.dispatch_request()
  File "C:\Users\UTILISATEUR\Desktop\WebAtrio\WebAtrio\env\lib\site-packages\flask\app.py", line 865, in dispatch_request
    return self.ensure_sync(self.view_functions[rule.endpoint])(**view_args)  # type: ignore[no-any-return]
  File "C:\Users\UTILISATEUR\Desktop\WebAtrio\WebAtrio\WebAtrio\views.py", line 8, in index
    return redirect(url_for('swagger'))
  File "C:\Users\UTILISATEUR\Desktop\WebAtrio\WebAtrio\env\lib\site-packages\flask\helpers.py", line 220, in url_for
    return current_app.url_for(
  File "C:\Users\UTILISATEUR\Desktop\WebAtrio\WebAtrio\env\lib\site-packages\flask\app.py", line 1084, in url_for
    return self.handle_url_build_error(error, endpoint, values)
  File "C:\Users\UTILISATEUR\Desktop\WebAtrio\WebAtrio\env\lib\site-packages\flask\app.py", line 1073, in url_for
    rv = url_adapter.build(  # type: ignore[union-attr]
  File "C:\Users\UTILISATEUR\Desktop\WebAtrio\WebAtrio\env\lib\site-packages\werkzeug\routing\map.py", line 926, in build
    raise BuildError(endpoint, values, method, self)
werkzeug.routing.exceptions.BuildError: Could not build url for endpoint 'swagger'. Did you mean 'swagger_ui' instead?
Exception on / [GET]
Traceback (most recent call last):
  File "C:\Users\UTILISATEUR\Desktop\WebAtrio\WebAtrio\env\lib\site-packages\flask\app.py", line 1473, in wsgi_app
    response = self.full_dispatch_request()
  File "C:\Users\UTILISATEUR\Desktop\WebAtrio\WebAtrio\env\lib\site-packages\flask\app.py", line 882, in full_dispatch_request
    rv = self.handle_user_exception(e)
  File "C:\Users\UTILISATEUR\Desktop\WebAtrio\WebAtrio\env\lib\site-packages\flask\app.py", line 880, in full_dispatch_request
    rv = self.dispatch_request()
  File "C:\Users\UTILISATEUR\Desktop\WebAtrio\WebAtrio\env\lib\site-packages\flask\app.py", line 865, in dispatch_request
    return self.ensure_sync(self.view_functions[rule.endpoint])(**view_args)  # type: ignore[no-any-return]
  File "C:\Users\UTILISATEUR\Desktop\WebAtrio\WebAtrio\WebAtrio\views.py", line 8, in index
    return redirect(url_for('swagger'))
  File "C:\Users\UTILISATEUR\Desktop\WebAtrio\WebAtrio\env\lib\site-packages\flask\helpers.py", line 220, in url_for
    return current_app.url_for(
  File "C:\Users\UTILISATEUR\Desktop\WebAtrio\WebAtrio\env\lib\site-packages\flask\app.py", line 1084, in url_for
    return self.handle_url_build_error(error, endpoint, values)
  File "C:\Users\UTILISATEUR\Desktop\WebAtrio\WebAtrio\env\lib\site-packages\flask\app.py", line 1073, in url_for
    rv = url_adapter.build(  # type: ignore[union-attr]
  File "C:\Users\UTILISATEUR\Desktop\WebAtrio\WebAtrio\env\lib\site-packages\werkzeug\routing\map.py", line 926, in build
    raise BuildError(endpoint, values, method, self)
werkzeug.routing.exceptions.BuildError: Could not build url for endpoint 'swagger'. Did you mean 'swagger_ui' instead?
Exception on / [GET]
Traceback (most recent call last):
  File "C:\Users\UTILISATEUR\Desktop\WebAtrio\WebAtrio\env\lib\site-packages\flask\app.py", line 1473, in wsgi_app
    response = self.full_dispatch_request()
  File "C:\Users\UTILISATEUR\Desktop\WebAtrio\WebAtrio\env\lib\site-packages\flask\app.py", line 882, in full_dispatch_request
    rv = self.handle_user_exception(e)
  File "C:\Users\UTILISATEUR\Desktop\WebAtrio\WebAtrio\env\lib\site-packages\flask\app.py", line 880, in full_dispatch_request
    rv = self.dispatch_request()
  File "C:\Users\UTILISATEUR\Desktop\WebAtrio\WebAtrio\env\lib\site-packages\flask\app.py", line 865, in dispatch_request
    return self.ensure_sync(self.view_functions[rule.endpoint])(**view_args)  # type: ignore[no-any-return]
  File "C:\Users\UTILISATEUR\Desktop\WebAtrio\WebAtrio\WebAtrio\views.py", line 8, in index
    return redirect(url_for('swagger'))
  File "C:\Users\UTILISATEUR\Desktop\WebAtrio\WebAtrio\env\lib\site-packages\flask\helpers.py", line 220, in url_for
    return current_app.url_for(
  File "C:\Users\UTILISATEUR\Desktop\WebAtrio\WebAtrio\env\lib\site-packages\flask\app.py", line 1084, in url_for
    return self.handle_url_build_error(error, endpoint, values)
  File "C:\Users\UTILISATEUR\Desktop\WebAtrio\WebAtrio\env\lib\site-packages\flask\app.py", line 1073, in url_for
    rv = url_adapter.build(  # type: ignore[union-attr]
  File "C:\Users\UTILISATEUR\Desktop\WebAtrio\WebAtrio\env\lib\site-packages\werkzeug\routing\map.py", line 926, in build
    raise BuildError(endpoint, values, method, self)
werkzeug.routing.exceptions.BuildError: Could not build url for endpoint 'swagger'. Did you mean 'swagger_ui' instead?
Exception on /persons/1 [DELETE]
Traceback (most recent call last):
  File "C:\Users\UTILISATEUR\Desktop\WebAtrio\env\lib\site-packages\sqlalchemy\engine\base.py", line 1971, in _exec_single_context
    self.dialect.do_execute(
  File "C:\Users\UTILISATEUR\Desktop\WebAtrio\env\lib\site-packages\sqlalchemy\engine\default.py", line 919, in do_execute
    cursor.execute(statement, parameters)
sqlite3.IntegrityError: NOT NULL constraint failed: jobs.person_id

The above exception was the direct cause of the following exception:

Traceback (most recent call last):
  File "C:\Users\UTILISATEUR\Desktop\WebAtrio\env\lib\site-packages\flask\app.py", line 1473, in wsgi_app
    response = self.full_dispatch_request()
  File "C:\Users\UTILISATEUR\Desktop\WebAtrio\env\lib\site-packages\flask\app.py", line 882, in full_dispatch_request
    rv = self.handle_user_exception(e)
  File "C:\Users\UTILISATEUR\Desktop\WebAtrio\env\lib\site-packages\flask_cors\extension.py", line 194, in wrapped_function
    return cors_after_request(app.make_response(f(*args, **kwargs)))
  File "C:\Users\UTILISATEUR\Desktop\WebAtrio\env\lib\site-packages\flask\app.py", line 880, in full_dispatch_request
    rv = self.dispatch_request()
  File "C:\Users\UTILISATEUR\Desktop\WebAtrio\env\lib\site-packages\flask\app.py", line 865, in dispatch_request
    return self.ensure_sync(self.view_functions[rule.endpoint])(**view_args)  # type: ignore[no-any-return]
  File "C:\Users\UTILISATEUR\Desktop\WebAtrio\WebAtrio\views.py", line 67, in handle_person
    db.session.commit()
  File "C:\Users\UTILISATEUR\Desktop\WebAtrio\env\lib\site-packages\sqlalchemy\orm\scoping.py", line 597, in commit
    return self._proxied.commit()
  File "C:\Users\UTILISATEUR\Desktop\WebAtrio\env\lib\site-packages\sqlalchemy\orm\session.py", line 1972, in commit
    trans.commit(_to_root=True)
  File "<string>", line 2, in commit
  File "C:\Users\UTILISATEUR\Desktop\WebAtrio\env\lib\site-packages\sqlalchemy\orm\state_changes.py", line 139, in _go
    ret_value = fn(self, *arg, **kw)
  File "C:\Users\UTILISATEUR\Desktop\WebAtrio\env\lib\site-packages\sqlalchemy\orm\session.py", line 1257, in commit
    self._prepare_impl()
  File "<string>", line 2, in _prepare_impl
  File "C:\Users\UTILISATEUR\Desktop\WebAtrio\env\lib\site-packages\sqlalchemy\orm\state_changes.py", line 139, in _go
    ret_value = fn(self, *arg, **kw)
  File "C:\Users\UTILISATEUR\Desktop\WebAtrio\env\lib\site-packages\sqlalchemy\orm\session.py", line 1232, in _prepare_impl
    self.session.flush()
  File "C:\Users\UTILISATEUR\Desktop\WebAtrio\env\lib\site-packages\sqlalchemy\orm\session.py", line 4296, in flush
    self._flush(objects)
  File "C:\Users\UTILISATEUR\Desktop\WebAtrio\env\lib\site-packages\sqlalchemy\orm\session.py", line 4432, in _flush
    transaction.rollback(_capture_exception=True)
  File "C:\Users\UTILISATEUR\Desktop\WebAtrio\env\lib\site-packages\sqlalchemy\util\langhelpers.py", line 146, in __exit__
    raise exc_value.with_traceback(exc_tb)
  File "C:\Users\UTILISATEUR\Desktop\WebAtrio\env\lib\site-packages\sqlalchemy\orm\session.py", line 4392, in _flush
    flush_context.execute()
  File "C:\Users\UTILISATEUR\Desktop\WebAtrio\env\lib\site-packages\sqlalchemy\orm\unitofwork.py", line 466, in execute
    rec.execute(self)
  File "C:\Users\UTILISATEUR\Desktop\WebAtrio\env\lib\site-packages\sqlalchemy\orm\unitofwork.py", line 642, in execute
    util.preloaded.orm_persistence.save_obj(
  File "C:\Users\UTILISATEUR\Desktop\WebAtrio\env\lib\site-packages\sqlalchemy\orm\persistence.py", line 85, in save_obj
    _emit_update_statements(
  File "C:\Users\UTILISATEUR\Desktop\WebAtrio\env\lib\site-packages\sqlalchemy\orm\persistence.py", line 912, in _emit_update_statements
    c = connection.execute(
  File "C:\Users\UTILISATEUR\Desktop\WebAtrio\env\lib\site-packages\sqlalchemy\engine\base.py", line 1422, in execute
    return meth(
  File "C:\Users\UTILISATEUR\Desktop\WebAtrio\env\lib\site-packages\sqlalchemy\sql\elements.py", line 514, in _execute_on_connection
    return connection._execute_clauseelement(
  File "C:\Users\UTILISATEUR\Desktop\WebAtrio\env\lib\site-packages\sqlalchemy\engine\base.py", line 1644, in _execute_clauseelement
    ret = self._execute_context(
  File "C:\Users\UTILISATEUR\Desktop\WebAtrio\env\lib\site-packages\sqlalchemy\engine\base.py", line 1850, in _execute_context
    return self._exec_single_context(
  File "C:\Users\UTILISATEUR\Desktop\WebAtrio\env\lib\site-packages\sqlalchemy\engine\base.py", line 1990, in _exec_single_context
    self._handle_dbapi_exception(
  File "C:\Users\UTILISATEUR\Desktop\WebAtrio\env\lib\site-packages\sqlalchemy\engine\base.py", line 2357, in _handle_dbapi_exception
    raise sqlalchemy_exception.with_traceback(exc_info[2]) from e
  File "C:\Users\UTILISATEUR\Desktop\WebAtrio\env\lib\site-packages\sqlalchemy\engine\base.py", line 1971, in _exec_single_context
    self.dialect.do_execute(
  File "C:\Users\UTILISATEUR\Desktop\WebAtrio\env\lib\site-packages\sqlalchemy\engine\default.py", line 919, in do_execute
    cursor.execute(statement, parameters)
sqlalchemy.exc.IntegrityError: (sqlite3.IntegrityError) NOT NULL constraint failed: jobs.person_id
[SQL: UPDATE jobs SET person_id=? WHERE jobs.id = ?]
[parameters: (None, 1)]
(Background on this error at: https://sqlalche.me/e/20/gkpj)
Exception on /persons/1 [DELETE]
Traceback (most recent call last):
  File "C:\Users\UTILISATEUR\Desktop\WebAtrio\env\lib\site-packages\sqlalchemy\engine\base.py", line 1971, in _exec_single_context
    self.dialect.do_execute(
  File "C:\Users\UTILISATEUR\Desktop\WebAtrio\env\lib\site-packages\sqlalchemy\engine\default.py", line 919, in do_execute
    cursor.execute(statement, parameters)
sqlite3.IntegrityError: NOT NULL constraint failed: jobs.person_id

The above exception was the direct cause of the following exception:

Traceback (most recent call last):
  File "C:\Users\UTILISATEUR\Desktop\WebAtrio\env\lib\site-packages\flask\app.py", line 1473, in wsgi_app
    response = self.full_dispatch_request()
  File "C:\Users\UTILISATEUR\Desktop\WebAtrio\env\lib\site-packages\flask\app.py", line 882, in full_dispatch_request
    rv = self.handle_user_exception(e)
  File "C:\Users\UTILISATEUR\Desktop\WebAtrio\env\lib\site-packages\flask_cors\extension.py", line 194, in wrapped_function
    return cors_after_request(app.make_response(f(*args, **kwargs)))
  File "C:\Users\UTILISATEUR\Desktop\WebAtrio\env\lib\site-packages\flask\app.py", line 880, in full_dispatch_request
    rv = self.dispatch_request()
  File "C:\Users\UTILISATEUR\Desktop\WebAtrio\env\lib\site-packages\flask\app.py", line 865, in dispatch_request
    return self.ensure_sync(self.view_functions[rule.endpoint])(**view_args)  # type: ignore[no-any-return]
  File "C:\Users\UTILISATEUR\Desktop\WebAtrio\WebAtrio\views.py", line 67, in handle_person
    db.session.commit()
  File "C:\Users\UTILISATEUR\Desktop\WebAtrio\env\lib\site-packages\sqlalchemy\orm\scoping.py", line 597, in commit
    return self._proxied.commit()
  File "C:\Users\UTILISATEUR\Desktop\WebAtrio\env\lib\site-packages\sqlalchemy\orm\session.py", line 1972, in commit
    trans.commit(_to_root=True)
  File "<string>", line 2, in commit
  File "C:\Users\UTILISATEUR\Desktop\WebAtrio\env\lib\site-packages\sqlalchemy\orm\state_changes.py", line 139, in _go
    ret_value = fn(self, *arg, **kw)
  File "C:\Users\UTILISATEUR\Desktop\WebAtrio\env\lib\site-packages\sqlalchemy\orm\session.py", line 1257, in commit
    self._prepare_impl()
  File "<string>", line 2, in _prepare_impl
  File "C:\Users\UTILISATEUR\Desktop\WebAtrio\env\lib\site-packages\sqlalchemy\orm\state_changes.py", line 139, in _go
    ret_value = fn(self, *arg, **kw)
  File "C:\Users\UTILISATEUR\Desktop\WebAtrio\env\lib\site-packages\sqlalchemy\orm\session.py", line 1232, in _prepare_impl
    self.session.flush()
  File "C:\Users\UTILISATEUR\Desktop\WebAtrio\env\lib\site-packages\sqlalchemy\orm\session.py", line 4296, in flush
    self._flush(objects)
  File "C:\Users\UTILISATEUR\Desktop\WebAtrio\env\lib\site-packages\sqlalchemy\orm\session.py", line 4432, in _flush
    transaction.rollback(_capture_exception=True)
  File "C:\Users\UTILISATEUR\Desktop\WebAtrio\env\lib\site-packages\sqlalchemy\util\langhelpers.py", line 146, in __exit__
    raise exc_value.with_traceback(exc_tb)
  File "C:\Users\UTILISATEUR\Desktop\WebAtrio\env\lib\site-packages\sqlalchemy\orm\session.py", line 4392, in _flush
    flush_context.execute()
  File "C:\Users\UTILISATEUR\Desktop\WebAtrio\env\lib\site-packages\sqlalchemy\orm\unitofwork.py", line 466, in execute
    rec.execute(self)
  File "C:\Users\UTILISATEUR\Desktop\WebAtrio\env\lib\site-packages\sqlalchemy\orm\unitofwork.py", line 642, in execute
    util.preloaded.orm_persistence.save_obj(
  File "C:\Users\UTILISATEUR\Desktop\WebAtrio\env\lib\site-packages\sqlalchemy\orm\persistence.py", line 85, in save_obj
    _emit_update_statements(
  File "C:\Users\UTILISATEUR\Desktop\WebAtrio\env\lib\site-packages\sqlalchemy\orm\persistence.py", line 912, in _emit_update_statements
    c = connection.execute(
  File "C:\Users\UTILISATEUR\Desktop\WebAtrio\env\lib\site-packages\sqlalchemy\engine\base.py", line 1422, in execute
    return meth(
  File "C:\Users\UTILISATEUR\Desktop\WebAtrio\env\lib\site-packages\sqlalchemy\sql\elements.py", line 514, in _execute_on_connection
    return connection._execute_clauseelement(
  File "C:\Users\UTILISATEUR\Desktop\WebAtrio\env\lib\site-packages\sqlalchemy\engine\base.py", line 1644, in _execute_clauseelement
    ret = self._execute_context(
  File "C:\Users\UTILISATEUR\Desktop\WebAtrio\env\lib\site-packages\sqlalchemy\engine\base.py", line 1850, in _execute_context
    return self._exec_single_context(
  File "C:\Users\UTILISATEUR\Desktop\WebAtrio\env\lib\site-packages\sqlalchemy\engine\base.py", line 1990, in _exec_single_context
    self._handle_dbapi_exception(
  File "C:\Users\UTILISATEUR\Desktop\WebAtrio\env\lib\site-packages\sqlalchemy\engine\base.py", line 2357, in _handle_dbapi_exception
    raise sqlalchemy_exception.with_traceback(exc_info[2]) from e
  File "C:\Users\UTILISATEUR\Desktop\WebAtrio\env\lib\site-packages\sqlalchemy\engine\base.py", line 1971, in _exec_single_context
    self.dialect.do_execute(
  File "C:\Users\UTILISATEUR\Desktop\WebAtrio\env\lib\site-packages\sqlalchemy\engine\default.py", line 919, in do_execute
    cursor.execute(statement, parameters)
sqlalchemy.exc.IntegrityError: (sqlite3.IntegrityError) NOT NULL constraint failed: jobs.person_id
[SQL: UPDATE jobs SET person_id=? WHERE jobs.id = ?]
[parameters: (None, 1)]
(Background on this error at: https://sqlalche.me/e/20/gkpj)
Exception on /persons/1 [DELETE]
Traceback (most recent call last):
  File "C:\Users\UTILISATEUR\Desktop\WebAtrio\env\lib\site-packages\sqlalchemy\engine\base.py", line 1971, in _exec_single_context
    self.dialect.do_execute(
  File "C:\Users\UTILISATEUR\Desktop\WebAtrio\env\lib\site-packages\sqlalchemy\engine\default.py", line 919, in do_execute
    cursor.execute(statement, parameters)
sqlite3.IntegrityError: NOT NULL constraint failed: jobs.person_id

The above exception was the direct cause of the following exception:

Traceback (most recent call last):
  File "C:\Users\UTILISATEUR\Desktop\WebAtrio\env\lib\site-packages\flask\app.py", line 1473, in wsgi_app
    response = self.full_dispatch_request()
  File "C:\Users\UTILISATEUR\Desktop\WebAtrio\env\lib\site-packages\flask\app.py", line 882, in full_dispatch_request
    rv = self.handle_user_exception(e)
  File "C:\Users\UTILISATEUR\Desktop\WebAtrio\env\lib\site-packages\flask_cors\extension.py", line 194, in wrapped_function
    return cors_after_request(app.make_response(f(*args, **kwargs)))
  File "C:\Users\UTILISATEUR\Desktop\WebAtrio\env\lib\site-packages\flask\app.py", line 880, in full_dispatch_request
    rv = self.dispatch_request()
  File "C:\Users\UTILISATEUR\Desktop\WebAtrio\env\lib\site-packages\flask\app.py", line 865, in dispatch_request
    return self.ensure_sync(self.view_functions[rule.endpoint])(**view_args)  # type: ignore[no-any-return]
  File "C:\Users\UTILISATEUR\Desktop\WebAtrio\WebAtrio\views.py", line 67, in handle_person
    db.session.commit()
  File "C:\Users\UTILISATEUR\Desktop\WebAtrio\env\lib\site-packages\sqlalchemy\orm\scoping.py", line 597, in commit
    return self._proxied.commit()
  File "C:\Users\UTILISATEUR\Desktop\WebAtrio\env\lib\site-packages\sqlalchemy\orm\session.py", line 1972, in commit
    trans.commit(_to_root=True)
  File "<string>", line 2, in commit
  File "C:\Users\UTILISATEUR\Desktop\WebAtrio\env\lib\site-packages\sqlalchemy\orm\state_changes.py", line 139, in _go
    ret_value = fn(self, *arg, **kw)
  File "C:\Users\UTILISATEUR\Desktop\WebAtrio\env\lib\site-packages\sqlalchemy\orm\session.py", line 1257, in commit
    self._prepare_impl()
  File "<string>", line 2, in _prepare_impl
  File "C:\Users\UTILISATEUR\Desktop\WebAtrio\env\lib\site-packages\sqlalchemy\orm\state_changes.py", line 139, in _go
    ret_value = fn(self, *arg, **kw)
  File "C:\Users\UTILISATEUR\Desktop\WebAtrio\env\lib\site-packages\sqlalchemy\orm\session.py", line 1232, in _prepare_impl
    self.session.flush()
  File "C:\Users\UTILISATEUR\Desktop\WebAtrio\env\lib\site-packages\sqlalchemy\orm\session.py", line 4296, in flush
    self._flush(objects)
  File "C:\Users\UTILISATEUR\Desktop\WebAtrio\env\lib\site-packages\sqlalchemy\orm\session.py", line 4432, in _flush
    transaction.rollback(_capture_exception=True)
  File "C:\Users\UTILISATEUR\Desktop\WebAtrio\env\lib\site-packages\sqlalchemy\util\langhelpers.py", line 146, in __exit__
    raise exc_value.with_traceback(exc_tb)
  File "C:\Users\UTILISATEUR\Desktop\WebAtrio\env\lib\site-packages\sqlalchemy\orm\session.py", line 4392, in _flush
    flush_context.execute()
  File "C:\Users\UTILISATEUR\Desktop\WebAtrio\env\lib\site-packages\sqlalchemy\orm\unitofwork.py", line 466, in execute
    rec.execute(self)
  File "C:\Users\UTILISATEUR\Desktop\WebAtrio\env\lib\site-packages\sqlalchemy\orm\unitofwork.py", line 642, in execute
    util.preloaded.orm_persistence.save_obj(
  File "C:\Users\UTILISATEUR\Desktop\WebAtrio\env\lib\site-packages\sqlalchemy\orm\persistence.py", line 85, in save_obj
    _emit_update_statements(
  File "C:\Users\UTILISATEUR\Desktop\WebAtrio\env\lib\site-packages\sqlalchemy\orm\persistence.py", line 912, in _emit_update_statements
    c = connection.execute(
  File "C:\Users\UTILISATEUR\Desktop\WebAtrio\env\lib\site-packages\sqlalchemy\engine\base.py", line 1422, in execute
    return meth(
  File "C:\Users\UTILISATEUR\Desktop\WebAtrio\env\lib\site-packages\sqlalchemy\sql\elements.py", line 514, in _execute_on_connection
    return connection._execute_clauseelement(
  File "C:\Users\UTILISATEUR\Desktop\WebAtrio\env\lib\site-packages\sqlalchemy\engine\base.py", line 1644, in _execute_clauseelement
    ret = self._execute_context(
  File "C:\Users\UTILISATEUR\Desktop\WebAtrio\env\lib\site-packages\sqlalchemy\engine\base.py", line 1850, in _execute_context
    return self._exec_single_context(
  File "C:\Users\UTILISATEUR\Desktop\WebAtrio\env\lib\site-packages\sqlalchemy\engine\base.py", line 1990, in _exec_single_context
    self._handle_dbapi_exception(
  File "C:\Users\UTILISATEUR\Desktop\WebAtrio\env\lib\site-packages\sqlalchemy\engine\base.py", line 2357, in _handle_dbapi_exception
    raise sqlalchemy_exception.with_traceback(exc_info[2]) from e
  File "C:\Users\UTILISATEUR\Desktop\WebAtrio\env\lib\site-packages\sqlalchemy\engine\base.py", line 1971, in _exec_single_context
    self.dialect.do_execute(
  File "C:\Users\UTILISATEUR\Desktop\WebAtrio\env\lib\site-packages\sqlalchemy\engine\default.py", line 919, in do_execute
    cursor.execute(statement, parameters)
sqlalchemy.exc.IntegrityError: (sqlite3.IntegrityError) NOT NULL constraint failed: jobs.person_id
[SQL: UPDATE jobs SET person_id=? WHERE jobs.id = ?]
[parameters: (None, 1)]
(Background on this error at: https://sqlalche.me/e/20/gkpj)
